<?xml version="1.0" ?>
<sdf version="1.7">
  <model name="alpha">
    <!-- Links -->
    <link name="base_footprint"/>



    <!-- Hydrodynamics plugin -->
<plugin
    filename="gz-sim-hydrodynamics-system"
    name="gz::sim::systems::Hydrodynamics">
  <link_name>base_link</link_name>
  <water_density>1000.0</water_density>

  <!-- Added mass: -->
  <xDotU>0</xDotU>
  <yDotV>0</yDotV>
  <zDotW>0</zDotW>
  <kDotP>0</kDotP>
  <mDotQ>0</mDotQ>
  <nDotR>0</nDotR>

  <!-- First order stability derivative: -->
  <xU>0</xU>
  <yV>0</yV>
  <zW>-2.0</zW>   <!-- Apply vertical damping -->
  <kP>-0.5</kP>
  <mQ>-0.5</mQ>
  <nR>-0.5</nR>

  <!-- Second order stability derivative: -->
  <xUabsU>-58.42</xUabsU>
  <yVabsV>-55.137</yVabsV>
  <zWabsW>-150.0</zWabsW>   <!-- Increase vertical drag for stabilization -->
  <kPabsP>-4.0</kPabsP>
  <mQabsQ>-4.0</mQabsQ>
  <nRabsR>-4.0</nRabsR>
</plugin>

    <!-- <plugin
      filename="gz-sim-buoyancy-system"
      name="gz::sim::systems::Buoyancy">
      <uniform_fluid_density>1000</uniform_fluid_density>
    </plugin> -->

    
    <link name="base_link">
      <visual name="visual">
        <geometry>
          <box>
            <size>0.001 0.001 0.001</size>
          </box>
        </geometry>
      </visual>
      <inertial>
        <mass>0.0001</mass>
        <inertia>
          <ixx>0.0001</ixx>
          <iyy>0.0001</iyy>
          <izz>0.0001</izz>
        </inertia>
      </inertial>
    </link>

    <link name="m3_inline_link">
      <visual name="visual">
        <geometry>
          <mesh>
            <uri>model://alpha/meshes/M3-INLINE.stl</uri>
          </mesh>
        </geometry>
      </visual>
      <collision name="collision">
        <geometry>
          <cylinder>
            <radius>0.02</radius>
            <length>0.150</length>
          </cylinder>
        </geometry>
      </collision>
      <inertial>
        <mass>0.341</mass>
        <inertia>
          <ixx>0.0000682</ixx>
          <iyy>0.000673</iyy>
          <izz>0.000673</izz>
        </inertia>
      </inertial>
    </link>

    <link name="m2_1_1_link">
      <visual name="visual">
        <geometry>
          <mesh>
            <uri>model://alpha/meshes/M2-1-1.stl</uri>
          </mesh>
        </geometry>
      </visual>
      <collision name="collision">
        <geometry>
          <cylinder>
            <radius>0.02</radius>
            <length>0.033</length>
          </cylinder>
        </geometry>
      </collision>
      <inertial>
        <mass>0.194</mass>
        <inertia>
          <ixx>0.000037</ixx>
          <iyy>0.000037</iyy>
          <izz>0.0000388</izz>
        </inertia>
      </inertial>
    </link>

    <link name="m2_joint_link">
      <visual name="visual">
        <geometry>
          <mesh>
            <uri>model://alpha/meshes/M2.stl</uri>
          </mesh>
        </geometry>
      </visual>
      <collision name="collision1">
        <geometry>
          <cylinder>
            <radius>0.02</radius>
            <length>0.145</length>
          </cylinder>
        </geometry>
      </collision>
      <collision name="collision2">
        <geometry>
          <cylinder>
            <radius>0.02</radius>
            <length>0.040</length>
          </cylinder>
        </geometry>
      </collision>
      <inertial>
        <mass>0.429</mass>
        <inertia>
          <ixx>0.0008907</ixx>
          <iyy>0.0008907</iyy>
          <izz>0.0000858</izz>
        </inertia>
      </inertial>
    </link>

    <link name="m2_1_2_link">
      <visual name="visual">
        <geometry>
          <mesh>
            <uri>model://alpha/meshes/M2-1-3.stl</uri>
          </mesh>
        </geometry>
      </visual>
      <collision name="collision">
        <geometry>
          <cylinder>
            <radius>0.02</radius>
            <length>0.033</length>
          </cylinder>
        </geometry>
      </collision>
      <inertial>
        <mass>0.115</mass>
        <inertia>
          <ixx>0.0000219</ixx>
          <iyy>0.0000219</iyy>
          <izz>0.000023</izz>
        </inertia>
      </inertial>
    </link>

    <link name="m1_link">
      <visual name="visual">
        <geometry>
          <mesh>
            <uri>model://alpha/meshes/RS1-100-101-123.stl</uri>
          </mesh>
        </geometry>
      </visual>
      <collision name="collision">
        <geometry>
          <cylinder>
            <radius>0.02</radius>
            <length>0.1</length>
          </cylinder>
        </geometry>
      </collision>
      <inertial>
        <mass>0.200</mass>
        <inertia>
          <ixx>0.0001867</ixx>
          <iyy>0.0001867</iyy>
          <izz>0.00004</izz>
        </inertia>
      </inertial>
    </link>

    

    <link name="ee_base_link">
      <visual name="visual">
        <geometry>
          <box>
            <size>0.001 0.001 0.001</size>
          </box>
        </geometry>
      </visual>
      <inertial>
        <mass>0.0001</mass>
        <inertia>
          <ixx>0.0001</ixx>
          <iyy>0.0001</iyy>
          <izz>0.0001</izz>
        </inertia>
      </inertial>
    </link>

    <link name="push_rod">
      <visual name="visual">
        <geometry>
          <box>
            <size>0.001 0.001 0.001</size>
          </box>
        </geometry>
      </visual>
      <inertial>
        <mass>0.0001</mass>
        <inertia>
          <ixx>0.0001</ixx>
          <iyy>0.0001</iyy>
          <izz>0.0001</izz>
        </inertia>
      </inertial>
    </link>

    <!-- Joints -->
    <joint name="base_joint" type="fixed">
      <parent>base_footprint</parent>
      <child>base_link</child>
    </joint>

    <joint name="axis_e" type="revolute">
      <parent>m3_inline_link</parent>
      <child>m2_1_1_link</child>
      <axis>
        <xyz>0 0 1</xyz>
      </axis>
      <limit>
        <lower>0.0</lower>
        <upper>6.10</upper>
        <effort>9.0</effort>
        <velocity>0.5</velocity>
      </limit>
    </joint>

    <joint name="axis_d" type="revolute">
      <parent>m2_1_1_link</parent>
      <child>m2_joint_link</child>
      <axis>
        <xyz>0 1 0</xyz>
      </axis>
      <limit>
        <lower>-3.49</lower>
        <upper>3.49</upper>
        <effort>9.0</effort>
        <velocity>0.5</velocity>
      </limit>
    </joint>

    <joint name="axis_c" type="revolute">
      <parent>m2_joint_link</parent>
      <child>m2_1_2_link</child>
      <axis>
        <xyz>0 1 0</xyz>
      </axis>
      <limit>
        <lower>0.0</lower>
        <upper>3.22</upper>
        <effort>9.0</effort>
        <velocity>0.5</velocity>
      </limit>
    </joint>

    <joint name="axis_b" type="revolute">
      <parent>m2_1_2_link</parent>
      <child>m1_link</child>
      <axis>
        <xyz>0 0 -1</xyz>
      </axis>
      <limit>
        <lower>0.0</lower>
        <upper>3.22</upper>
        <effort>9.0</effort>
        <velocity>0.5</velocity>
      </limit>
    </joint>

    <joint name="ee_joint" type="fixed">
      <parent>m1_link</parent>
      <child>ee_base_link</child>
    </joint>

    <joint name="axis_a" type="prismatic">
      <parent>ee_base_link</parent>
      <child>push_rod</child>
      <axis>
        <xyz>0 0 1</xyz>
      </axis>
      <limit>
        <lower>0</lower>
        <upper>0.015</upper>
        <effort>10</effort>
        <velocity>10</velocity>
      </limit>
    </joint>

    <!-- Joint Controllers -->
    <plugin filename="gz-sim-joint-trajectory-controller-system" name="gz::sim::systems::JointTrajectoryController">
      <joint_name>axis_a</joint_name>
      <joint_name>axis_b</joint_name>
      <joint_name>axis_c</joint_name>
      <joint_name>axis_d</joint_name>
      <joint_name>axis_e</joint_name>
    </plugin>

  </model>

  <world name="default">
    <gravity>0 0 -9.81</gravity>
  </world>
</sdf>

